Workbook

Sheet 01_خلاصه_مدیریتی
A1: داشبورد جامع مدیریت ریسک اعتباری و شاخص‌های کلیدی سبد صیادی
A2: سامانه هوشمند مدیریت اعتباری صیاد | تاریخ مبنای استعلام: 1405/06/15 | زمان تولید گزارش: 1405/06/16 ساعت 08:29:11 | مبنای محاسبات: تجمیع تک‌باره صادرکننده یکتا و حذف قطعی خطای دوباره‌شماری
A4: شاخص‌های کلیدی سبد اعتباری (Portfolio KPIs)
A5: شاخص کلیدی | B5: مقدار عددی | C5: واحد سنجش | D5: توضیحات و تفکیک نظارتی
A6: تعداد کل صادرکنندگان دارای پروفایل بانکی معتبر | B6: 46 | C6: نفر | D6: صادرکنندگان احراز هویت شده و فعال اعتباری در شبکه صیاد
A7: تعداد کل اسناد و چک‌های نزد صندوق | B7: 147 | C7: فقره | D7: ۱۴۶ چک صیادی بانکی + ۱ سند سفته معاف
A8: مجموع ارزش ریالی اسناد و چک‌های صندوق | B8: 483325000000 | C8: ریال | D8: تعهد مستقیم فیزیکی نزد صندوق (۴۸.۳۳۲ میلیارد تومان)
A9: مجموع ارزش ریالی چک‌های صندوق مشتریان معتبر | B9: 479705000000 | C9: ریال | D9: تفاضل ۳.۶۲ میلیارد ریال در اسناد معاف و حل‌نشده
A10: مجموع چک‌های در راه بانکی (تجمیع تک‌باره) | B10: 4856322051407 | C10: ریال | D10: تعهدات در گردش صادرکنندگان در کل شبکه بانکی
A11: مجموع چک‌های برگشتی بانکی (تجمیع تک‌باره) | B11: 244751000000 | C11: 244751000000 | D11: برگشتی فعال صادرکنندگان (بدون دوباره‌شماری تکراری)
A12: مجموع مبالغ رفع سوءاثر شده صادرکنندگان | B12: 1109486999968 | C12: ریال | D12: سابقه تسویه و آزادسازی موفق صادرکنندگان در شبکه
A13: مجموع کل تعهدات فعال بانکی (در راه + برگشتی) | B13: 5101073051407 | C13: ریال | D13: کل بار تعهدی فعال صادرکنندگان در شبکه بانکی
A14: نسبت چک‌های برگشتی به تعهد فعال | B14: 4.8 | C14: درصد | D14: نسبت کل برگشتی به تعهد فعال بانکی (~۴.۸۰٪)
A15: شاخص تمرکز هرفیندال-هیرشمن (HHI) | B15: 1407.27 | C15: واحد | D15: تمرکز متوسط رو به بالا در مطالبات معوق بانکی
A16: سهم تمرکز ۱۰ صادرکننده پرریسک صدر جدول | B16: 96.6 | C16: درصد | D16: ۲۳۶.۴۲۵ میلیارد ریال از ۲۴۴.۷۵۱ میلیارد ریال برگشتی
A17: تعداد صادرکنندگان دارای چک برگشتی فعال | B17: =COUNTIF('02_مشتریان_یکتا'!K4:K49, ">0") | C17: نفر | D17: ۱۳ صادرکننده با برگشتی مثبت در میان ۴۶ پروفایل معتبر بانکی
A19: بیانیه الزامی نظارتی و ممیزی عدم دوباره‌شماری: «محاسبات بانکی بر اساس مشتری یکتا انجام شد و هیچ مبلغ در راه/برگشتی/رفع سوءاثر به دلیل تعدد چک دوباره‌شماری نشده است»
A22: توزیع طبقات پنج‌گانه ریسک اعتباری صادرکنندگان (Risk Tiers)
A23: طبقه ریسک | B23: بازه امتیاز | C23: تعداد صادرکننده | D23: درصد جمعیتی | E23: تعهدات صندوق (ریال) | F23: راهبرد عملیاتی
A24: اقدام فوری (Immediate Action) | B24: ۸۱ تا ۱۰۰ | C24: =COUNTIF('02_مشتریان_یکتا'!$R$4:$R$49, "اقدام فوری") | D24: =C24/$B$6 | E24: =SUMIFS('02_مشتریان_یکتا'!$H$4:$H$49, '02_مشتریان_یکتا'!$R$4:$R$49, "اقدام فوری") | F24: توقف فوری افزایش اعتبار، ضبط وثایق و پیگیری حقوقی وصول
A25: پرریسک (High Risk) | B25: ۶۱ تا ۸۰ | C25: =COUNTIF('02_مشتریان_یکتا'!$R$4:$R$49, "پرریسک") | D25: =C25/$B$6 | E25: =SUMIFS('02_مشتریان_یکتا'!$H$4:$H$49, '02_مشتریان_یکتا'!$R$4:$R$49, "پرریسک") | F25: درخواست وثیقه ملکی/نقد، کاهش سقف و کنترل مستمر
A26: مراقبت (Watch List) | B26: ۴۱ تا ۶۰ | C26: =COUNTIF('02_مشتریان_یکتا'!$R$4:$R$49, "مراقبت") | D26: =C26/$B$6 | E26: =SUMIFS('02_مشتریان_یکتا'!$H$4:$H$49, '02_مشتریان_یکتا'!$R$4:$R$49, "مراقبت") | F26: اخذ تضمین فرعی، تبدیل چک مدت‌دار به نقد، پایش هفتگی و روزانه
A27: عادی (Normal) | B27: ۲۱ تا ۴۰ | C27: =COUNTIF('02_مشتریان_یکتا'!$R$4:$R$49, "عادی") | D27: =C27/$B$6 | E27: =SUMIFS('02_مشتریان_یکتا'!$H$4:$H$49, '02_مشتریان_یکتا'!$R$4:$R$49, "عادی") | F27: روال استاندارد اعتباری و پایش سررسیدها
A28: کم‌ریسک (Low Risk) | B28: ۰ تا ۲۰ | C28: =COUNTIF('02_مشتریان_یکتا'!$R$4:$R$49, "کم‌ریسک") | D28: =C28/$B$6 | E28: =SUMIFS('02_مشتریان_یکتا'!$H$4:$H$49, '02_مشتریان_یکتا'!$R$4:$R$49, "کم‌ریسک") | F28: پذیرش چک و اعطای سقف حداکثری تسهیلات تجاری
A29: مجموع کل طبقات اعتباری | B29: - | C29: =SUM(C24:C28) | D29: =SUM(D24:D28) | E29: =SUM(E24:E28) | F29: تطابق ۱۰۰٪ با ۴۶ پروفایل معتبر و ۴۷۹.۷۰۵ میلیارد ریال صندوق
A31: ۱۰ صادرکننده پرریسک صدر جدول و شاخص تمرکز هرفیندال (Top 10 High-Risk Issuers)
A32: رتبه | B32: نام صادرکننده | C32: کدملی صادرکننده | D32: مبلغ برگشتی بانکی (ریال) | E32: سهم از کل برگشتی | F32: سهم تجمعی (٪) | G32: سهم در HHI | H32: امتیاز ریسک | I32: رده ریسک | J32: تصمیم اعتباری سامانه
A33: 1 | B33: حسین حشمتی | C33: 0933387075 | D33: 56960000000 | E33: 0.23272632 | F33: 0.2327 | G33: 541.62 | H33: 85 | I33: اقدام فوری | J33: مسدودسازی کامل تسهیلات، مطالبه وثیقه ملکی/نقدی، اقدام حقوقی و وصول آنی.
A34: 2 | B34: وحید زوار | C34: 6430003159 | D34: 46080000000 | E34: 0.18827298 | F34: 0.421 | G34: 354.47 | H34: 78 | I34: پرریسک | J34: مسدودسازی سقف تسهیلات، اخذ وثیقه ملکی/نقدی، پایش فشرده و کاهش تعهدات.
A35: 3 | B35: محمد رفیق طرقی | C35: 0890543331 | D35: 40300000000 | E35: 0.16465714 | F35: 0.5857 | G35: 271.12 | H35: 78 | I35: پرریسک | J35: مسدودسازی سقف تسهیلات، اخذ وثیقه ملکی/نقدی، پایش فشرده و کاهش تعهدات.
A36: 4 | B36: محمدجواد وفادار عیدگاهی | C36: 0924020865 | D36: 21630000000 | E36: 0.088375533 | F36: 0.674 | G36: 78.1 | H36: 78 | I36: پرریسک | J36: مسدودسازی سقف تسهیلات، اخذ وثیقه ملکی/نقدی، پایش فشرده و کاهش تعهدات.
A37: 5 | B37: محمد ضیافتی مالدار | C37: 0922236992 | D37: 19160000000 | E37: 0.078283643 | F37: 0.7523 | G37: 61.28 | H37: 72 | I37: پرریسک | J37: مسدودسازی سقف تسهیلات، اخذ وثیقه ملکی/نقدی، پایش فشرده و کاهش تعهدات.
A38: 6 | B38: ابوالفضل شافعی | C38: 0941987231 | D38: 12800000000 | E38: 0.05229805 | F38: 0.8046 | G38: 27.35 | H38: 72 | I38: پرریسک | J38: مسدودسازی سقف تسهیلات، اخذ وثیقه ملکی/نقدی، پایش فشرده و کاهش تعهدات.
A39: 7 | B39: زهرا بهرامی پویا | C39: 0927624011 | D39: 12300000000 | E39: 0.050255157 | F39: 0.8549 | G39: 25.26 | H39: 72 | I39: پرریسک | J39: مسدودسازی سقف تسهیلات، اخذ وثیقه ملکی/نقدی، پایش فشرده و کاهش تعهدات.
A40: 8 | B40: احمد زحمتکش باجگیران | C40: 0860270361 | D40: 11550000000 | E40: 0.047190818 | F40: 0.9021 | G40: 22.27 | H40: 72 | I40: پرریسک | J40: مسدودسازی سقف تسهیلات، اخذ وثیقه ملکی/نقدی، پایش فشرده و کاهش تعهدات.
A41: 9 | B41: محمد زاهدی آغوی | C41: 0690489838 | D41: 9398000000 | E41: 0.038398209 | F41: 0.9405 | G41: 14.74 | H41: 65 | I41: پرریسک | J41: مسدودسازی سقف تسهیلات، اخذ وثیقه ملکی/نقدی، پایش فشرده و کاهش تعهدات.
A42: 10 | B42: وحید اشرافیان | C42: 0921320711 | D42: 6247000000 | E42: 0.0255239 | F42: 0.966 | G42: 6.51 | H42: 65 | I42: پرریسک | J42: بهبود جزئی؛ تثبیت و انسداد سقف، ادامه تضمین و پایش روزانه.
A43: مجموع ۱۰ صادرکننده اول | D43: =SUM(D33:D42) | E43: =SUM(E33:E42) | F43: =F42 | G43: =SUM(G33:G42) | J43: تمرکز ۹۶.۶۰٪ کل برگشتی در ۱۰ مشتری اول

Sheet 02_مشتریان_یکتا
A1: جدول مرجع مشتریان یکتا و تجمیع تک‌باره اطلاعات اعتباری (Canonical Customers Master Table)
A2: تفکیک قطعی تعهدات مستقیم صندوق از وضعیت بانکی صادرکننده | محاسبه امتیاز ریسک ۰ تا ۱۰۰ با رعایت کامل کف‌های اجباری F1 تا F6 | محاسبات بانکی بر اساس مشتری یکتا انجام شد و هیچ مبلغ در راه/برگشتی/رفع سوءاثر به دلیل تعدد چک دوباره‌شماری نشده است
A3: ردیف | B3: کد مشتری | C3: کد ملی صادرکننده | D3: نام و نام خانوادگی صادرکننده | E3: وضعیت هویت | F3: رنگ اعتباری | G3: تعداد چک در صندوق | H3: مجموع مبلغ چک‌های صندوق (ریال) | I3: سهم از صندوق | J3: مبلغ چک‌های در راه بانکی (ریال) | K3: مبلغ چک‌های برگشتی بانکی (ریال) | L3: مبلغ رفع سوءاثر بانکی (ریال) | M3: رده پایداری | N3: تعداد دوره‌های برگشتی | O3: نمره خام ریسک | P3: کف اعمال‌شده | Q3: امتیاز نهایی ریسک | R3: طبقه ریسک | S3: تصمیم اعتباری سامانه‌ای
A4: 1 | B4: 2 | C4: 0933387075 | D4: حسین حشمتی | E4: VERIFIED | F4: قرمز | G4: 1 | H4: 1060000000 | I4: 0.0022096914 | J4: 2500000000 | K4: 56960000000 | L4: 0 | M4: NEW | N4: 2 | O4: 50.77 | P4: 85 | Q4: 85 | R4: اقدام فوری | S4: مسدودسازی کامل تسهیلات، مطالبه وثیقه ملکی/نقدی، اقدام حقوقی و وصول آنی.
A5: 2 | B5: 3 | C5: 0922236992 | D5: محمد ضیافتی مالدار | E5: VERIFIED | F5: قرمز | G5: 8 | H5: 53520000000 | I5: 0.11156857 | J5: 1144807000000 | K5: 19160000000 | L5: 305078252000 | M5: CHRONIC | N5: 10 | O5: 31.74 | P5: 72 | Q5: 72 | R5: پرریسک | S5: مسدودسازی سقف تسهیلات، اخذ وثیقه ملکی/نقدی، پایش فشرده و کاهش تعهدات.
A6: 3 | B6: 4 | C6: 6510002647 | D6: سیدجمال موسوی علی آبادی | E6: VERIFIED | F6: قرمز | G6: 2 | H6: 3000000000 | I6: 0.0062538435 | J6: 35090000000 | K6: 2800000000 | L6: 14938000000 | M6: CHRONIC | N6: 6 | O6: 20.87 | P6: 45 | Q6: 45 | R6: مراقبت | S6: داده تاریخی؛ مسدودسازی سقف تسهیلات و پایش روزانه تا دریافت استعلام معتبر جدید.
A7: 4 | B7: 5 | C7: 0941987231 | D7: ابوالفضل شافعی | E7: VERIFIED | F7: قرمز | G7: 1 | H7: 7500000000 | I7: 0.015634609 | J7: 46230000000 | K7: 12800000000 | L7: 18135000000 | M7: CHRONIC | N7: 10 | O7: 46.62 | P7: 72 | Q7: 72 | R7: پرریسک | S7: مسدودسازی سقف تسهیلات، اخذ وثیقه ملکی/نقدی، پایش فشرده و کاهش تعهدات.
A8: 5 | B8: 6 | C8: 0860010198 | D8: جواد همتی | E8: VERIFIED | F8: سفید | G8: 1 | H8: 9400000000 | I8: 0.019595376 | J8: 17878097081 | K8: 0 | L8: 6960472000 | M8: CLEAN | N8: 0 | O8: 0.16 | P8: - | Q8: 0.16 | R8: کم‌ریسک | S8: پذیرش چک روال عادی و ادامه تعامل در سقف مصوب.
A9: 6 | B9: 7 | C9: 6510019418 | D9: محمد طاهری | E9: VERIFIED | F9: سفید | G9: 1 | H9: 6000000000 | I9: 0.012507687 | J9: 145073541953 | K9: 0 | L9: 62716596171 | M9: CLEAN | N9: 0 | O9: 0 | P9: - | Q9: 0 | R9: کم‌ریسک | S9: پذیرش چک روال عادی و ادامه تعامل در سقف مصوب.
A10: 7 | B10: 8 | C10: 0946492190 | D10: علیرضا یعقوبی | E10: VERIFIED | F10: سفید | G10: 1 | H10: 1740000000 | I10: 0.0036272292 | J10: 26680000000 | K10: 0 | L10: 37000000 | M10: CLEAN | N10: 0 | O10: 0 | P10: - | Q10: 0 | R10: کم‌ریسک | S10: پذیرش چک روال عادی و ادامه تعامل در سقف مصوب.
A11: 8 | B11: 9 | C11: 0942904257 | D11: مرتضی پیروزیان | E11: VERIFIED | F11: سفید | G11: 6 | H11: 6000000000 | I11: 0.012507687 | J11: 20290000000 | K11: 0 | L11: 2605000000 | M11: CLEAN | N11: 0 | O11: 0 | P11: - | Q11: 0 | R11: کم‌ریسک | S11: پذیرش چک روال عادی و ادامه تعامل در سقف مصوب.
A12: 9 | B12: 10 | C12: 2298907366 | D12: عطاری یدالله | E12: VERIFIED | F12: سفید | G12: 12 | H12: 24000000000 | I12: 0.050030748 | J12: 28000000000 | K12: 0 | L12: 240000000 | M12: CLEAN | N12: 0 | O12: 2.33 | P12: - | Q12: 2.33 | R12: کم‌ریسک | S12: پذیرش چک روال عادی و ادامه تعامل در سقف مصوب.
A13: 10 | B13: 11 | C13: 0941314121 | D13: جواد غفوریان قالی باف | E13: VERIFIED | F13: سفید | G13: 7 | H13: 7000000000 | I13: 0.014592302 | J13: 28682000000 | K13: 0 | L13: 14295000000 | M13: INTERMITTENT | N13: 3 | O13: 0 | P13: 45 | Q13: 45 | R13: مراقبت | S13: رفع سوءاثر کامل ثبت شد؛ دوره گذار پایش و پایش روزانه. هرگونه ارتقای سقف تا تأیید دوره‌های بعدی ممنوع است.
A14: 11 | B14: 12 | C14: 5228890297 | D14: طاهره حسنی | E14: VERIFIED | F14: سفید | G14: 5 | H14: 15500000000 | I14: 0.032311525 | J14: 145613735000 | K14: 0 | L14: 59466770010 | M14: CLEAN | N14: 0 | O14: 0 | P14: - | Q14: 0 | R14: کم‌ریسک | S14: پذیرش چک روال عادی و ادامه تعامل در سقف مصوب.
A15: 12 | B15: 13 | C15: 2110152184 | D15: فرهنگ نیا مهزیار | E15: VERIFIED | F15: سفید | G15: 1 | H15: 895000000 | I15: 0.00186573 | J15: 191578500000 | K15: 0 | L15: 3548318000 | M15: CLEAN | N15: 0 | O15: 0 | P15: - | Q15: 0 | R15: کم‌ریسک | S15: پذیرش چک روال عادی و ادامه تعامل در سقف مصوب.
A16: 13 | B16: 14 | C16: 0920541526 | D16: عقیل نرمکی | E16: VERIFIED | F16: سفید | G16: 4 | H16: 4640000000 | I16: 0.0096726113 | J16: 61089499998 | K16: 0 | L16: 1018900000 | M16: CLEAN | N16: 0 | O16: 0.04 | P16: - | Q16: 0.04 | R16: کم‌ریسک | S16: پذیرش چک روال عادی و ادامه تعامل در سقف مصوب.
A17: 14 | B17: 16 | C17: 0860270361 | D17: احمد زحمتکش باجگیران | E17: VERIFIED | F17: قرمز | G17: 3 | H17: 4200000000 | I17: 0.0087553809 | J17: 135058325000 | K17: 11550000000 | L17: 5534728000 | M17: CHRONIC | N17: 10 | O17: 32.39 | P17: 72 | Q17: 72 | R17: پرریسک | S17: مسدودسازی سقف تسهیلات، اخذ وثیقه ملکی/نقدی، پایش فشرده و کاهش تعهدات.
A18: 15 | B18: 17 | C18: 0922030936 | D18: عباس مقنی | E18: VERIFIED | F18: سفید | G18: 4 | H18: 42320000000 | I18: 0.088220886 | J18: 224823000000 | K18: 0 | L18: 30402825000 | M18: NEW | N18: 2 | O18: 7.11 | P18: - | Q18: 7.11 | R18: کم‌ریسک | S18: پذیرش چک روال عادی و ادامه تعامل در سقف مصوب.
A19: 16 | B19: 18 | C19: 1920394974 | D19: وحید محمدی انور | E19: VERIFIED | F19: قرمز | G19: 2 | H19: 7400000000 | I19: 0.015426147 | J19: 12989000000 | K19: 4200000000 | L19: 11807500000 | M19: CHRONIC | N19: 10 | O19: 52.93 | P19: 45 | Q19: 52.93 | R19: مراقبت | S19: رخداد برگشتی جدید (+۳.۷B)؛ انسداد سقف تسهیلات، اخذ وثیقه و پایش روزانه.
A20: 17 | B20: 19 | C20: 0920630138 | D20: مرتضی موذن | E20: VERIFIED | F20: سفید | G20: 12 | H20: 5220000000 | I20: 0.010881688 | J20: 47434500000 | K20: 0 | L20: 890000000 | M20: CLEAN | N20: 0 | O20: 4.95 | P20: - | Q20: 4.95 | R20: کم‌ریسک | S20: پذیرش چک روال عادی و ادامه تعامل در سقف مصوب.
A21: 18 | B21: 20 | C21: 0921320711 | D21: وحید اشرافیان | E21: VERIFIED | F21: قرمز | G21: 2 | H21: 1465000000 | I21: 0.0030539602 | J21: 263677279312 | K21: 6247000000 | L21: 13523000000 | M21: CHRONIC | N21: 10 | O21: 24.1 | P21: 65 | Q21: 65 | R21: پرریسک | S21: بهبود جزئی؛ تثبیت و انسداد سقف، ادامه تضمین و پایش روزانه.
A22: 19 | B22: 21 | C22: 6430003159 | D22: وحید زوار | E22: VERIFIED | F22: قرمز | G22: 5 | H22: 13350000000 | I22: 0.027829604 | J22: 294823500000 | K22: 46080000000 | L22: 152016000000 | M22: CHRONIC | N22: 10 | O22: 49.89 | P22: 78 | Q22: 78 | R22: پرریسک | S22: مسدودسازی سقف تسهیلات، اخذ وثیقه ملکی/نقدی، پایش فشرده و کاهش تعهدات.
A23: 20 | B23: 22 | C23: 0943162041 | D23: حمید مددی | E23: VERIFIED | F23: سفید | G23: 2 | H23: 1990000000 | I23: 0.0041483829 | J23: 17294955324 | K23: 0 | L23: 2371300000 | M23: CLEAN | N23: 0 | O23: 0 | P23: - | Q23: 0 | R23: کم‌ریسک | S23: پذیرش چک روال عادی و ادامه تعامل در سقف مصوب.
A24: 21 | B24: 23 | C24: 0690489838 | D24: محمد زاهدی آغوی | E24: VERIFIED | F24: قرمز | G24: 2 | H24: 8890000000 | I24: 0.018532223 | J24: 59290930000 | K24: 9398000000 | L24: 52840962000 | M24: CHRONIC | N24: 10 | O24: 28 | P24: 65 | Q24: 65 | R24: پرریسک | S24: مسدودسازی سقف تسهیلات، اخذ وثیقه ملکی/نقدی، پایش فشرده و کاهش تعهدات.
A25: 22 | B25: 25 | C25: 0923318895 | D25: وارسته شهریاران سعید | E25: VERIFIED | F25: سفید | G25: 3 | H25: 37350000000 | I25: 0.077860352 | J25: 55660000000 | K25: 0 | L25: 86140000 | M25: CLEAN | N25: 0 | O25: 3.65 | P25: - | Q25: 3.65 | R25: کم‌ریسک | S25: پذیرش چک روال عادی و ادامه تعامل در سقف مصوب.
A26: 23 | B26: 26 | C26: 0941876578 | D26: علیرضا ضرغام مقدم | E26: VERIFIED | F26: سفید | G26: 1 | H26: 350000000 | I26: 0.00072961508 | J26: 7370540000 | K26: 0 | L26: 781900000 | M26: CLEAN | N26: 0 | O26: 0 | P26: - | Q26: 0 | R26: کم‌ریسک | S26: پذیرش چک روال عادی و ادامه تعامل در سقف مصوب.
A27: 24 | B27: 27 | C27: 5220146602 | D27: اسدیان سوهان حمید | E27: VERIFIED | F27: سفید | G27: 3 | H27: 6800000000 | I27: 0.014175379 | J27: 50434720000 | K27: 0 | L27: 5332712000 | M27: CLEAN | N27: 0 | O27: 0 | P27: - | Q27: 0 | R27: کم‌ریسک | S27: پذیرش چک روال عادی و ادامه تعامل در سقف مصوب.
A28: 25 | B28: 28 | C28: 0922010536 | D28: محمدباقر مشیری | E28: VERIFIED | F28: سفید | G28: 5 | H28: 10950000000 | I28: 0.022826529 | J28: 48136400000 | K28: 0 | L28: 35000000 | M28: CLEAN | N28: 0 | O28: 0 | P28: - | Q28: 0 | R28: کم‌ریسک | S28: پذیرش چک روال عادی و ادامه تعامل در سقف مصوب.
A29: 26 | B29: 30 | C29: 0010485295 | D29: فرید والی | E29: VERIFIED | F29: سفید | G29: 1 | H29: 4000000000 | I29: 0.008338458 | J29: 58720000000 | K29: 0 | L29: 750000000 | M29: CLEAN | N29: 0 | O29: 1.57 | P29: - | Q29: 1.57 | R29: کم‌ریسک | S29: پذیرش چک روال عادی و ادامه تعامل در سقف مصوب.
A30: 27 | B30: 31 | C30: 5229804221 | D30: سیدمهدی راستگو | E30: VERIFIED | F30: سفید | G30: 4 | H30: 10480000000 | I30: 0.02184676 | J30: 12980000000 | K30: 0 | L30: 0 | M30: CLEAN | N30: 0 | O30: 0 | P30: - | Q30: 0 | R30: کم‌ریسک | S30: پذیرش چک روال عادی و ادامه تعامل در سقف مصوب.
A31: 28 | B31: 32 | C31: 6519917109 | D31: ام لیلا کلاه درازی | E31: VERIFIED | F31: سفید | G31: 1 | H31: 600000000 | I31: 0.0012507687 | J31: 6420000000 | K31: 0 | L31: 0 | M31: CLEAN | N31: 0 | O31: 0 | P31: - | Q31: 0 | R31: کم‌ریسک | S31: پذیرش چک روال عادی و ادامه تعامل در سقف مصوب.
A32: 29 | B32: 33 | C32: 0720388619 | D32: افشاری قزقاوه سجاد | E32: VERIFIED | F32: سفید | G32: 1 | H32: 320000000 | I32: 0.00066707664 | J32: 28996595380 | K32: 0 | L32: 360000000 | M32: CLEAN | N32: 0 | O32: 0 | P32: - | Q32: 0 | R32: کم‌ریسک | S32: پذیرش چک روال عادی و ادامه تعامل در سقف مصوب.
A33: 30 | B33: 34 | C33: 0681855436 | D33: امین داوری | E33: VERIFIED | F33: سفید | G33: 4 | H33: 5600000000 | I33: 0.011673841 | J33: 97789824945 | K33: 0 | L33: 45367735500 | M33: CLEAN | N33: 0 | O33: 0 | P33: - | Q33: 0 | R33: کم‌ریسک | S33: پذیرش چک روال عادی و ادامه تعامل در سقف مصوب.
A34: 31 | B34: 35 | C34: 0780642813 | D34: حامد نهاردانی | E34: VERIFIED | F34: سفید | G34: 2 | H34: 2700000000 | I34: 0.0056284592 | J34: 172534650000 | K34: 0 | L34: 75010839287 | M34: INTERMITTENT | N34: 3 | O34: 10 | P34: - | Q34: 10 | R34: کم‌ریسک | S34: پذیرش چک روال عادی و ادامه تعامل در سقف مصوب.
A35: 32 | B35: 36 | C35: 0924020865 | D35: محمدجواد وفادار عیدگاهی | E35: VERIFIED | F35: قرمز | G35: 4 | H35: 5520000000 | I35: 0.011507072 | J35: 91680000000 | K35: 21630000000 | L35: 43715000000 | M35: CHRONIC | N35: 10 | O35: 36.32 | P35: 78 | Q35: 78 | R35: پرریسک | S35: مسدودسازی سقف تسهیلات، اخذ وثیقه ملکی/نقدی، پایش فشرده و کاهش تعهدات.
A36: 33 | B36: 37 | C36: 0880141281 | D36: محمد ابراهیمی دشت بیاض | E36: VERIFIED | F36: سفید | G36: 4 | H36: 1950000000 | I36: 0.0040649983 | J36: 101507099414 | K36: 0 | L36: 26820000000 | M36: CLEAN | N36: 0 | O36: 0.2 | P36: - | Q36: 0.2 | R36: کم‌ریسک | S36: پذیرش چک روال عادی و ادامه تعامل در سقف مصوب.
A37: 34 | B37: 38 | C37: 0932151930 | D37: ملکه محمدی | E37: VERIFIED | F37: سفید | G37: 1 | H37: 935000000 | I37: 0.0019491146 | J37: 8350000000 | K37: 0 | L37: 0 | M37: CLEAN | N37: 0 | O37: 1.14 | P37: - | Q37: 1.14 | R37: کم‌ریسک | S37: پذیرش چک روال عادی و ادامه تعامل در سقف مصوب.
A38: 35 | B38: 39 | C38: 6439490842 | D38: نصرت شیدا | E38: VERIFIED | F38: سفید | G38: 1 | H38: 340000000 | I38: 0.00070876893 | J38: 2430800000 | K38: 0 | L38: 96600000 | M38: CLEAN | N38: 0 | O38: 0 | P38: - | Q38: 0 | R38: کم‌ریسک | S38: پذیرش چک روال عادی و ادامه تعامل در سقف مصوب.
A39: 36 | B39: 40 | C39: 0890543331 | D39: محمد رفیق طرقی | E39: VERIFIED | F39: قرمز | G39: 1 | H39: 15000000000 | I39: 0.031269218 | J39: 265665000000 | K39: 40300000000 | L39: 81847500000 | M39: CHRONIC | N39: 10 | O39: 61.38 | P39: 78 | Q39: 78 | R39: پرریسک | S39: مسدودسازی سقف تسهیلات، اخذ وثیقه ملکی/نقدی، پایش فشرده و کاهش تعهدات.
A40: 37 | B40: 41 | C40: 0924049650 | D40: محمد حمیدی شیرغان | E40: VERIFIED | F40: سفید | G40: 2 | H40: 3940000000 | I40: 0.0082133811 | J40: 17880000000 | K40: 0 | L40: 10283000000 | M40: CLEAN | N40: 0 | O40: 2.21 | P40: - | Q40: 2.21 | R40: کم‌ریسک | S40: پذیرش چک روال عادی و ادامه تعامل در سقف مصوب.
...

Sheet 03_رخدادهای_امروز
A1: لاگ رخدادهای اعتباری و پایش تحولات استعلام امروز (Today's Credit Events & Inquiries)
A2: کشف هوشمند رخدادهای انتقال تعهد در راه به برگشتی و رفع سوءاثر واقعی | پرونده‌های شاخص: زهرا بهرامی پویا (-۳.۵B در راه / +۳.۵B برگشتی)، طرقی، محمدی، موسوی، زحمتکش و غفوریان
A3: ردیف | B3: نام مشتری / صادرکننده | C3: کد ملی صادرکننده | D3: نوع رویداد اعتباری | E3: مبلغ قبلی در راه (ریال) | F3: مبلغ جدید در راه (ریال) | G3: تغییر در راه (ریال) | H3: مبلغ قبلی برگشتی (ریال) | I3: مبلغ جدید برگشتی (ریال) | J3: تغییر برگشتی (ریال) | K3: مبلغ خالص رویداد (ریال) | L3: سطح قطعیت | M3: زمان آخرین استعلام | N3: شرح تشخیصی سامانه
A4: 1 | B4: ابوالفضل شافعی | C4: 0941987231 | D4: انتقال تعهد در راه به برگشتی | E4: 53730000000 | F4: 46230000000 | G4: -7500000000 | H4: 5300000000 | I4: 12800000000 | J4: 7500000000 | K4: 7500000000 | L4: قطعی (CERTAIN) | M4: 2026-09-06 20:00:00 | N4: انتقال مبلغ 7,500,000,000 ریال از وضعیت در راه به برگشتی در پرونده ابوالفضل شافعی (کدملی 0941987231) با ضریب اطمینان قطعی (۱۰۰٪ تطابق ریاضی).
A5: 2 | B5: محمد رفیق طرقی | C5: 0890543331 | D5: انتقال تعهد در راه به برگشتی | E5: 270965000000 | F5: 265665000000 | G5: -5300000000 | H5: 35000000000 | I5: 40300000000 | J5: 5300000000 | K5: 5300000000 | L5: قطعی (CERTAIN) | M5: 2026-09-06 09:21:59 | N5: انتقال مبلغ 5,300,000,000 ریال از وضعیت در راه به برگشتی در پرونده محمد رفیق طرقی (کدملی 0890543331) با ضریب اطمینان قطعی (۱۰۰٪ تطابق ریاضی).
A6: 3 | B6: وحید محمدی انور | C6: 1920394974 | D6: انتقال تعهد در راه به برگشتی | E6: 16689000000 | F6: 12989000000 | G6: -3700000000 | H6: 500000000 | I6: 4200000000 | J6: 3700000000 | K6: 3700000000 | L6: قطعی (CERTAIN) | M6: 2026-09-06 09:21:49 | N6: انتقال مبلغ 3,700,000,000 ریال از وضعیت در راه به برگشتی در پرونده وحید محمدی انور (کدملی 1920394974) با ضریب اطمینان قطعی (۱۰۰٪ تطابق ریاضی).
A7: 4 | B7: زهرا بهرامی پویا | C7: 0927624011 | D7: انتقال تعهد در راه به برگشتی | E7: 342330000000 | F7: 338830000000 | G7: -3500000000 | H7: 8800000000 | I7: 12300000000 | J7: 3500000000 | K7: 3500000000 | L7: قطعی (CERTAIN) | M7: 2026-09-06 20:00:00 | N7: انتقال مبلغ 3,500,000,000 ریال از وضعیت در راه به برگشتی در پرونده زهرا بهرامی پویا (کدملی 0927624011) با ضریب اطمینان قطعی (۱۰۰٪ تطابق ریاضی).
A8: 5 | B8: سیدجمال موسوی علی آبادی | C8: 6510002647 | D8: انتقال تعهد در راه به برگشتی | E8: 36590000000 | F8: 35090000000 | G8: -1500000000 | H8: 1300000000 | I8: 2800000000 | J8: 1500000000 | K8: 1500000000 | L8: قطعی (CERTAIN) | M8: 2026-09-05 08:43:51 | N8: انتقال مبلغ 1,500,000,000 ریال از وضعیت در راه به برگشتی در پرونده سیدجمال موسوی علی آبادی (کدملی 6510002647) با ضریب اطمینان قطعی (۱۰۰٪ تطابق ریاضی). (منشأ داده: REUSED_VALID_SUCCESS - رخداد از آخرین استعلام معتبر، نه الزاماً امروز)
A9: 6 | B9: احمد زحمتکش باجگیران | C9: 0860270361 | D9: انتقال تعهد در راه به برگشتی | E9: 136458325000 | F9: 135058325000 | G9: -1400000000 | H9: 10150000000 | I9: 11550000000 | J9: 1400000000 | K9: 1400000000 | L9: قطعی (CERTAIN) | M9: 2026-09-06 09:23:48 | N9: انتقال مبلغ 1,400,000,000 ریال از وضعیت در راه به برگشتی در پرونده احمد زحمتکش باجگیران (کدملی 0860270361) با ضریب اطمینان قطعی (۱۰۰٪ تطابق ریاضی).
A10: 7 | B10: جواد غفوریان قالی باف | C10: 0941314121 | D10: رفع سوءاثر واقعی و تسویه برگشتی | E10: - | F10: - | G10: - | H10: 1000000000 | I10: 0 | J10: -1000000000 | K10: 1000000000 | L10: قطعی (CERTAIN) | M10: 2026-09-06 20:00:00 | N10: کاهش 1,000,000,000 ریال از برگشتی و افزایش دقیق 1,000,000,000 ریال در رفع سوءاثر پرونده جواد غفوریان قالی باف (کدملی 0941314121).
A11: 8 | B11: وحید اشرافیان | C11: 0921320711 | D11: بهبود جزئی و کاهش برگشتی | E11: - | F11: - | G11: - | H11: 6417000000 | I11: 6247000000 | J11: -170000000 | K11: 780000000 | L11: بالا (HIGH) | M11: 2026-09-06 20:00:00 | N11: بهبود جزئی / کاهش 170,000,000 ریال از برگشتی همراه با افزایش 780,000,000 ریال رفع سوءاثر، اما بدون تطابق مبلغ کامل در پرونده وحید اشرافیان (کدملی 0921320711).

Sheet 04_اقدام_فوری
A1: فهرست مشتریان مشمول اقدام فوری اعتباری (Immediate Action Required - Score 81-100)
A2: مشتریان دارای ریسک بحرانی و برگشتی سنگین؛ توقف بلادرنگ افزایش اعتبار، ضبط وثایق و پیگیری حقوقی وصول
A3: ردیف | B3: نام صادرکننده | C3: کد ملی صادرکننده | D3: امتیاز ریسک | E3: طبقه ریسک | F3: مجموع تعهدات صندوق (ریال) | G3: مبلغ برگشتی بانکی (ریال) | H3: مبلغ در راه بانکی (ریال) | I3: سابقه دوره‌های برگشتی | J3: علل اصلی ورود به رده بحرانی | K3: اقدامات الزامی و پروتکل حقوقی
A4: 1 | B4: حسین حشمتی | C4: 0933387075 | D4: 85 | E4: اقدام فوری | F4: 1060000000 | G4: 56960000000 | H4: 2500000000 | I4: 2 دوره (برگشتی مزمن) | J4: مبلغ برگشتی بالای ۵۰ میلیارد ریال (مشروط به کف اجباری ۸۵) و سابقه مزمن عدم تسویه | K4: انسداد فوری حساب صندوق، ضبط و واخواست چک‌های نزد صندوق، ارسال اظهارنامه رسمی قضایی

Sheet 05_مراقبت
A1: فهرست مشتریان تحت مراقبت و پایش اعتباری (Watch List - Score 41-60)
A2: مشتریان دارای نوسان اعتباری یا سابقه برگشتی متناوب؛ اخذ تضمین فرعی، عدم افزایش حد اعتباری و نظارت هفتگی
A3: ردیف | B3: نام صادرکننده | C3: کد ملی صادرکننده | D3: امتیاز ریسک | E3: رده ریسک | F3: تعهدات صندوق (ریال) | G3: مبلغ برگشتی بانکی (ریال) | H3: مبلغ در راه بانکی (ریال) | I3: سابقه دوره‌های برگشتی | J3: علل قرارگیری در مراقبت | K3: اقدامات پیشگیرانه و مراقبتی
A4: 1 | B4: وحید محمدی انور | C4: 1920394974 | D4: 52.93 | E4: مراقبت | F4: 7400000000 | G4: 4200000000 | H4: 12989000000 | I4: 10 دوره | J4: برگشتی فعال ۴.۲ میلیارد ریالی و سابقه ۱۰ دوره برگشتی در استعلام‌های تاریخی | K4: اخذ تضمین فرعی، پایش روزانه، عدم افزایش اعتبار و نظارت مستمر بر مبالغ در راه
A5: 2 | B5: سیدجمال موسوی علی آبادی | C5: 6510002647 | D5: 45 | E5: مراقبت | F5: 3000000000 | G5: 2800000000 | H5: 35090000000 | I5: 6 دوره | J5: برگشتی فعال ۱.۵ میلیارد ریالی، انتقال تعهد در راه به برگشتی و سابقه ۶ دوره برگشتی | K5: پایش روزانه، کنترل وصولی‌ها و عدم پذیرش چک جدید بدون وثیقه نقد
A6: 3 | B6: میلاد دلجو | C6: 2710183331 | D6: 45 | E6: مراقبت | F6: 27500000000 | G6: 1326000000 | H6: 93388000000 | I6: 8 دوره | J6: ریسک تمرکز بالای تعهدات نزد صندوق (۲۷.۵ میلیارد ریال) و برگشتی فعال ۱.۳۲۶ میلیارد ریالی | K6: اخذ تضمین فرعی، کنترل استعلام‌های آتی، پایش هفتگی و عدم افزایش تعهدات
A7: 4 | B7: جواد غفوریان قالی باف | C7: 0941314121 | D7: 45 | E7: مراقبت | F7: 7000000000 | G7: 0 | H7: 28682000000 | I7: 3 دوره | J7: دوره گذار پایش پس از تسویه ۱ میلیارد ریال چک برگشتی؛ اعمال کف ۴۵ مراقبت | K7: پایش روزانه، کنترل چک‌های در راه، عدم افزایش سقف اعتباری (دوره گذار پایش پس از تسویه)

Sheet 06_بهبود
A1: مشتریان دارای روند بهبود و رفع سوءاثر مستند (Clearance & Recovery)
A2: صادرکنندگانی که کاهش مستند در مبالغ برگشتی و افزایش معادل در مبالغ رفع سوءاثر ثبت کرده‌اند (تسویه موفق)
A3: ردیف | B3: نام صادرکننده | C3: کد ملی صادرکننده | D3: مبلغ رفع سوءاثر جدید (ریال) | E3: کاهش در مبلغ برگشتی (ریال) | F3: مبلغ فعلی برگشتی (ریال) | G3: مبلغ در راه بانکی (ریال) | H3: امتیاز فعلی ریسک | I3: وضعیت اعتباری سامانه | J3: مجوز تمدید و ارزیابی
A4: 1 | B4: جواد غفوریان قالی باف | C4: 0941314121 | D4: 1000000000 | E4: 1000000000 | F4: 0 | G4: 28682000000 | H4: 45 | I4: دوره گذار پایش (مراقبت) | J4: تسویه اخیر ۱ میلیارد ریال؛ دوره گذار پایش، پایش روزانه، تثبیت سقف و ممنوعیت ارتقای تعهدات
A5: 2 | B5: وحید اشرافیان | C5: 0921320711 | D5: 780000000 | E5: 170000000 | F5: 6247000000 | G5: 263677279312 | H5: 65 | I5: بهبود نسبی (پرریسک) | J5: بهبود نسبی، پایش روزانه، تثبیت سقف تسهیلات، درخواست تضمین تکمیلی

Sheet 07_چکهای_تفصیلی
A1: KolCode | B1: چک|شماره | C1: چک|نوع | D1: Bank | E1: CodeIn | F1: IdRAdif | G1: سند|شماره | H1: سند|تاریخ | I1: Mode | J1: MoeCode | K1: چک|تاریخ | L1: چک|مبلغ | M1: چک|شرح | N1: Shahr_Code | O1: چک|بانک | P1: KolCode2 | Q1: MoeCode2 | R1: چک|در وجه | S1: DateDaryaft | T1: Selected | U1: SumKol | V1: Rang | W1: چک|نوع | X1: CodeMAvalDore
A2: 1105 | B2: 1113333 | C2: c | D2: 1 | E2: 1933 | F2: 98201 | G2: 1403144 | H2: 14030520 | I2: 0 | J2: 1001 | K2: 14030901 | L2: 2000000000 | N2: 0 | O2: * قر سفته | P2: 1110 | Q2: 656 | R2: اميرحسين عليپور چک هاي برگشتي | S2: 14030520 | T2: FALSE | U2: جمع 483,325,000,000 | V2: 9721058 | W2: دريافتي | X2: 0
A3: 1105 | B3: 057751 | C3: c | D3: 11 | E3: 1931 | F3: 98053 | G3: 1403142 | H3: 14030518 | I3: 0 | J3: 1001 | K3: 14031220 | L3: 1060000000 | M3: 2380030072556088 | N3: 0 | O3: * ايران زمين مفتح مشهد | P3: 1110 | Q3: 586 | R3: اميرحسين عليپور | S3: 14030518 | T3: FALSE | U3: جمع 483,325,000,000 | V3: 9721058 | W3: دريافتي | X3: 0
A4: 1105 | B4: 180057 | C4: c | D4: 3 | E4: 3052 | F4: 148447 | G4: 1404346 | H4: 14041210 | I4: 0 | J4: 1001 | K4: 14050501 | L4: 16000000000 | M4: 5138040187866685 | N4: 0 | O4: * بانک ملي کوي المهدي | P4: 1110 | Q4: 689 | R4: ملک هاشميه | S4: 14041210 | T4: FALSE | U4: جمع 483,325,000,000 | V4: 7327703 | W4: دريافتي | X4: 0
A5: 1105 | B5: 400697 | C5: c | D5: 21 | E5: 3025 | F5: 147627 | G5: 1404334 | H5: 14041128 | I5: 0 | J5: 1001 | K5: 14050528 | L5: 1500000000 | M5: 9147040164254882 | N5: 0 | O5: * قرض الحسنه رسالت بانکداري اجتماعي | P5: 1110 | Q5: 605 | R5: اقاي ضيافتي | S5: 14041128 | T5: FALSE | U5: جمع 483,325,000,000 | W5: دريافتي | X5: 0
A6: 1105 | B6: 695631 | C6: c | D6: 10 | E6: 3215 | F6: 153919 | G6: 1405062 | H6: 14050231 | I6: 0 | J6: 1001 | K6: 14050530 | L6: 7500000000 | M6: 9700040200262950 | N6: 0 | O6: * شهر ميدان راهنمايي مشهد | P6: 1110 | Q6: 605 | R6: اقاي ضيافتي | S6: 14050231 | T6: FALSE | U6: جمع 483,325,000,000 | W6: دريافتي | X6: 0
A7: 1105 | B7: 970083 | C7: c | D7: 3 | E7: 2144 | F7: 111643 | G7: 1403281 | H7: 14031005 | I7: 0 | J7: 1001 | K7: 14050601 | L7: 5660000000 | M7: 5080030099110169 | N7: 0 | O7: * بانک ملي کوي المهدي 8601 | P7: 1110 | Q7: 689 | R7: ملک هاشميه | S7: 14031005 | T7: FALSE | U7: جمع 483,325,000,000 | V7: 0 | W7: دريافتي | X7: 0
A8: 1105 | B8: 734272 | C8: c | D8: 6 | E8: 3121 | F8: 151371 | G8: 1405030 | H8: 14050130 | I8: 0 | J8: 1001 | K8: 14050601 | L8: 9400000000 | M8: 7515050006253687 | N8: 0 | O8: * رفاه هاشميه مشهد | P8: 1110 | Q8: 605 | R8: اقاي ضيافتي | S8: 14050130 | T8: FALSE | U8: جمع 483,325,000,000 | W8: دريافتي | X8: 0
A9: 1105 | B9: 793454 | C9: c | D9: 3 | E9: 3233 | F9: 154817 | G9: 1405075 | H9: 14050313 | I9: 0 | J9: 1001 | K9: 14050601 | L9: 6000000000 | M9: 7413040073308914 | N9: 0 | O9: * بانک ملي شهداي گمنام تربت حيدريه | P9: 1110 | Q9: 605 | R9: اقاي ضيافتي | S9: 14050313 | T9: FALSE | U9: جمع 483,325,000,000 | W9: دريافتي | X9: 0
A10: 1105 | B10: 14444 | C10: c | D10: 12 | E10: 3316 | F10: 158191 | G10: 1405125 | H10: 14050501 | I10: 0 | J10: 1001 | K10: 14050601 | L10: 870000000 | N10: 0 | O10: * کشاورزي دکتر حسابي | P10: 1110 | Q10: 767 | R10: اقاي عليرضا يعقوبي خريدار تارا | S10: 14050501 | T10: FALSE | U10: جمع 483,325,000,000 | W10: دريافتي | X10: 0
A11: 1105 | B11: 135598 | C11: c | D11: 21 | E11: 3343 | F11: 158997 | G11: 1405135 | H11: 14050511 | I11: 0 | J11: 1001 | K11: 14050601 | L11: 1000000000 | M11: 8140050019357728 | N11: 0 | O11: * قرض الحسنه رسالت بانکداري اجتماعي | P11: 1110 | Q11: 596 | R11: مرتضي پيروزيان | S11: 14050511 | T11: FALSE | U11: جمع 483,325,000,000 | W11: دريافتي | X11: 0
A12: 1105 | B12: 810231 | C12: c | D12: 9 | E12: 3297 | F12: 157413 | G12: 1405114 | H12: 14050421 | I12: 0 | J12: 1001 | K12: 14050602 | L12: 2000000000 | M12: 2011030010355250 | N12: 0 | O12: * صادرات صفاشم | P12: 1110 | Q12: 605 | R12: اقاي ضيافتي | S12: 14050421 | T12: FALSE | U12: جمع 483,325,000,000 | W12: دريافتي | X12: 0
A13: 1105 | B13: 239933 | C13: c | D13: 12 | E13: 3318 | F13: 158299 | G13: 1405127 | H13: 14050503 | I13: 0 | J13: 1001 | K13: 14050603 | L13: 1000000000 | M13: 2679040061560087 | N13: 0 | O13: * کشاورزي شريعتي | P13: 1110 | Q13: 605 | R13: اقاي ضيافتي | S13: 14050503 | T13: FALSE | U13: جمع 483,325,000,000 | W13: دريافتي | X13: 0
A14: 1105 | B14: 189764 | C14: c | D14: 3 | E14: 2902 | F14: 142719 | G14: 1404268 | H14: 14040922 | I14: 0 | J14: 1001 | K14: 14050605 | L14: 3100000000 | M14: 1748040121634559 | N14: 0 | O14: * بانک ملي کوي المهدي | P14: 1110 | Q14: 605 | R14: اقاي ضيافتي | S14: 14040922 | T14: FALSE | U14: جمع 483,325,000,000 | W14: دريافتي | X14: 0
A15: 1105 | B15: 756139 | C15: c | D15: 9 | E15: 3217 | F15: 153927 | G15: 1405062 | H15: 14050231 | I15: 0 | J15: 1001 | K15: 14050605 | L15: 895000000 | M15: 3778020108164326 | N15: 0 | O15: * صادرات کوي اب و برق | P15: 1110 | Q15: 605 | R15: اقاي ضيافتي | S15: 14050231 | T15: FALSE | U15: جمع 483,325,000,000 | W15: دريافتي | X15: 0
A16: 1105 | B16: 030616 | C16: c | D16: 14 | E16: 3149 | F16: 151905 | G16: 1405037 | H16: 14050206 | I16: 0 | J16: 1001 | K16: 14050606 | L16: 1160000000 | M16: 5561040153416463 | N16: 0 | O16: * سپه سيدي مشهد | P16: 1110 | Q16: 605 | R16: اقاي ضيافتي | S16: 14050206 | T16: FALSE | U16: جمع 483,325,000,000 | W16: دريافتي | X16: 0
A17: 1105 | B17: 804984 | C17: c | D17: 14 | E17: 2997 | F17: 145985 | G17: 1404312 | H17: 14041106 | I17: 0 | J17: 1001 | K17: 14050610 | L17: 1380000000 | M17: 1907030071639288 | N17: 0 | O17: * سپه امام رضا فريمان | P17: 1110 | Q17: 605 | R17: اقاي ضيافتي | S17: 14041106 | T17: FALSE | U17: جمع 483,325,000,000 | W17: دريافتي | X17: 0
A18: 1105 | B18: 66666 | C18: c | D18: 3 | E18: 3236 | F18: 154883 | G18: 1405078 | H18: 14050316 | I18: 0 | J18: 1001 | K18: 14050610 | L18: 1400000000 | M18: چک تمديد احمد زحمتکش | N18: 0 | O18: * بانک ملي کوي المهدي | P18: 1110 | Q18: 605 | R18: اقاي ضيافتي | S18: 14050316 | T18: FALSE | U18: جمع 483,325,000,000 | W18: دريافتي | X18: 0
A19: 1105 | B19: 902051 | C19: c | D19: 14 | E19: 3285 | F19: 156667 | G19: 1405103 | H19: 14050410 | I19: 0 | J19: 1001 | K19: 14050610 | L19: 6200000000 | M19: 5560050044994051 | N19: 0 | O19: * سپه بلوار فرودگاه | P19: 1110 | Q19: 605 | R19: اقاي ضيافتي | S19: 14050410 | T19: FALSE | U19: جمع 483,325,000,000 | W19: دريافتي | X19: 0
A20: 1105 | B20: 6288190 | C20: c | D20: 22 | E20: 3311 | F20: 157453 | G20: 1405115 | H20: 14050422 | I20: 0 | J20: 1001 | K20: 14050610 | L20: 3700000000 | M20: 6919040140728884 | N20: 0 | O20: * پست بانک ايران مرکزي مشهد | P20: 1110 | Q20: 605 | R20: اقاي ضيافتي | S20: 14050422 | T20: FALSE | U20: جمع 483,325,000,000 | W20: دريافتي | X20: 0
A21: 1105 | B21: 327252 | C21: c | D21: 9 | E21: 3247 | F21: 155055 | G21: 1405079 | H21: 14050317 | I21: 0 | J21: 1001 | K21: 14050611 | L21: 400000000 | M21: 889304019406437 | N21: 0 | O21: * صادرات معلم | P21: 1110 | Q21: 9 | R21: آقاي مرتضي موذن | S21: 14050317 | T21: FALSE | U21: جمع 483,325,000,000 | W21: دريافتي | X21: 0
A22: 1105 | B22: 400696 | C22: c | D22: 21 | E22: 3024 | F22: 147625 | G22: 1404334 | H22: 14041128 | I22: 0 | J22: 1001 | K22: 14050612 | L22: 1500000000 | M22: 4946040164254881 | N22: 0 | O22: * قرض الحسنه رسالت بانکداري اجتماعيي | P22: 1110 | Q22: 605 | R22: اقاي ضيافتي | S22: 14041128 | T22: FALSE | U22: جمع 483,325,000,000 | W22: دريافتي | X22: 0
... A63: 1105 | B63: 2999903 | C63: c | D63: 12 | E63: 3315 | F63: 157863 | G63: 1405121 | H63: 14050428 | I63: 0 | J63: 1001 | K63: 14050725 | L63: 15000000000 | M63: 4317050049334681 | N63: 0 | O63: * کشاورزي امام رضا | P63: 1110 | Q63: 605 | R63: اقاي ضيافتي | S63: 14050428 | T63: FALSE | U63: جمع 483,325,000,000 | W63: دريافتي | X63: 0
A64: 1105 | B64: 970085 | C64: c | D64: 3 | E64: 2146 | F64: 111647 | G64: 1403281 | H64: 14031005 | I64: 0 | J64: 1001 | K64: 14050801 | L64: 5660000000 | M64: 6200030099110171 | N64: 0 | O64: * بانک ملي کوي المهدي 8601 | P64: 1110 | Q64: 689 | R64: ملک هاشميه | S64: 14031005 | T64: FALSE | U64: جمع 483,325,000,000 | V64: 0 | W64: دريافتي | X64: 0
A65: 1105 | B65: 33878317 | C65: c | D65: 15 | E65: 3143 | F65: 151809 | G65: 1405036 | H65: 14050205 | I65: 0 | J65: 1001 | K65: 14050801 | L65: 2620000000 | M65: 2400040184813904 | N65: 0 | O65: * ملت دانش اموز | P65: 1110 | Q65: 605 | R65: اقاي ضيافتي | S65: 14050205 | T65: FALSE | U65: جمع 483,325,000,000 | W65: دريافتي | X65: 0
A66: 1105 | B66: 135600 | C66: c | D66: 21 | E66: 3345 | F66: 159001 | G66: 1405135 | H66: 14050511 | I66: 0 | J66: 1001 | K66: 14050801 | L66: 1000000000 | M66: 5540050019357730 | N66: 0 | O66: * قرض الحسنه رسالت بانکداري اجتماعيي | P66: 1110 | Q66: 596 | R66: مرتضي پيروزيان | S66: 14050511 | T66: FALSE | U66: جمع 483,325,000,000 | W66: دريافتي | X66: 0
A67: 1105 | B67: 810233 | C67: c | D67: 9 | E67: 3299 | F67: 157417 | G67: 1405114 | H67: 14050421 | I67: 0 | J67: 1001 | K67: 14050802 | L67: 2000000000 | M67: 5533030010355252 | N67: 0 | O67: * صادرات صفاشم | P67: 1110 | Q67: 605 | R67: اقاي ضيافتي | S67: 14050421 | T67: FALSE | U67: جمع 483,325,000,000 | W67: دريافتي | X67: 0
A68: 1105 | B68: 239935 | C68: c | D68: 12 | E68: 3320 | F68: 158303 | G68: 1405127 | H68: 14050503 | I68: 0 | J68: 1001 | K68: 14050803 | L68: 1000000000 | M68: 6663040061560089 | N68: 0 | O68: * کشاورزي شريعتي | P68: 1110 | Q68: 605 | R68: اقاي ضيافتي | S68: 14050503 | T68: FALSE | U68: جمع 483,325,000,000 | W68: دريافتي | X68: 0
A69: 1105 | B69: 189766 | C69: c | D69: 3 | E69: 2904 | F69: 142723 | G69: 1404268 | H69: 14040922 | I69: 0 | J69: 1001 | K69: 14050805 | L69: 3100000000 | M69: 4962040121634561 | N69: 0 | O69: * بانک ملي کوي المهدي | P69: 1110 | Q69: 605 | R69: اقاي ضيافتي | S69: 14040922 | T69: FALSE | U69: جمع 483,325,000,000 | W69: دريافتي | X69: 0
A70: 1105 | B70: 902052 | C70: c | D70: 14 | E70: 3284 | F70: 156665 | G70: 1405103 | H70: 14050410 | I70: 0 | J70: 1001 | K70: 14050805 | L70: 6800000000 | M70: 9515050044994052 | N70: 0 | O70: * سپه بلوار فرودگاه مشهد | P70: 1110 | Q70: 605 | R70: اقاي ضيافتي | S70: 14050410 | T70: FALSE | U70: جمع 483,325,000,000 | W70: دريافتي | X70: 0
A71: 1105 | B71: 349379 | C71: c | D71: 14 | E71: 3043 | F71: 148191 | G71: 1404341 | H71: 14041205 | I71: 0 | J71: 1001 | K71: 14050806 | L71: 1400000000 | M71: 2512020042035577 | N71: 0 | O71: * سپه امام خميني | P71: 1110 | Q71: 758 | R71: ميلاد داوري | S71: 14041205 | T71: FALSE | U71: جمع 483,325,000,000 | W71: دريافتي | X71: 0
A72: 1105 | B72: 030618 | C72: c | D72: 14 | E72: 3151 | F72: 151909 | G72: 1405037 | H72: 14050206 | I72: 0 | J72: 1001 | K72: 14050806 | L72: 1160000000 | M72: 3478040153416465 | N72: 0 | O72: * سپه سيدي مشهد | P72: 1110 | Q72: 605 | R72: اقاي ضيافتي | S72: 14050206 | T72: FALSE | U72: جمع 483,325,000,000 | W72: دريافتي | X72: 0
A73: 1105 | B73: 00769517 | C73: c | D73: 15 | E73: 3205 | F73: 153665 | G73: 1405059 | H73: 14050228 | I73: 0 | J73: 1001 | K73: 14050807 | L73: 1350000000 | M73: 9154040120076061 | N73: 0 | O73: * ملت عطا ملک سبزوار | P73: 1110 | Q73: 605 | R73: اقاي ضيافتي | S73: 14050228 | T73: FALSE | U73: جمع 483,325,000,000 | W73: دريافتي | X73: 0
A74: 1105 | B74: 623498 | C74: c | D74: 9 | E74: 2783 | F74: 139439 | G74: 1404230 | H74: 14040814 | I74: 0 | J74: 1001 | K74: 14050810 | L74: 1000000000 | M74: 8691020116968671 | N74: 0 | O74: * صادرات مهرآباد 1904281 | P74: 1110 | Q74: 605 | R74: اقاي ضيافتي | S74: 14040814 | T74: FALSE | U74: جمع 483,325,000,000 | W74: دريافتي | X74: 0
A75: 1105 | B75: 804986 | C75: c | D75: 14 | E75: 2995 | F75: 145981 | G75: 1404312 | H75: 14041106 | I75: 0 | J75: 1001 | K75: 14050810 | L75: 1380000000 | M75: 5755030071639290 | N75: 0 | O75: * سپه امام رضا فريمان | P75: 1110 | Q75: 605 | R75: اقاي ضيافتي | S75: 14041106 | T75: FALSE | U75: جمع 483,325,000,000 | W75: دريافتي | X75: 0
A76: 1105 | B76: 795571 | C76: c | D76: 6 | E76: 2746 | F76: 138447 | G76: 1404221 | H76: 14040805 | I76: 0 | J76: 1001 | K76: 14050815 | L76: 570000000 | M76: 1509040118622468 | N76: 0 | O76: * رفاه بيمارستان امام رضا کد 1301111 | P76: 1110 | Q76: 605 | R76: اقاي ضيافتي | S76: 14040805 | T76: FALSE | U76: جمع 483,325,000,000 | W76: دريافتي | X76: 0
... A86: 1105 | B86: 685158 | C86: c | D86: 6 | E86: 3099 | F86: 150901 | G86: 1405024 | H86: 14050124 | I86: 0 | J86: 1001 | K86: 14050830 | L86: 360000000 | M86: 9377040091817634 | N86: 0 | O86: * رفاه مفتح | P86: 1110 | Q86: 769 | R86: اقاي حسين زاده خريدار کوييک 1402ار | S86: 14050124 | T86: FALSE | U86: جمع 483,325,000,000 | W86: دريافتي | X86: 0
A87: 1105 | B87: 970086 | C87: c | D87: 3 | E87: 2147 | F87: 111649 | G87: 1403281 | H87: 14031005 | I87: 0 | J87: 1001 | K87: 14050901 | L87: 5660000000 | M87: 2718030099110172 | N87: 0 | O87: * بانک ملي کوي المهدي | P87: 1110 | Q87: 689 | R87: ملک هاشميه | S87: 14031005 | T87: FALSE | U87: جمع 483,325,000,000 | V87: 0 | W87: دريافتي | X87: 0
A88: 1105 | B88: 33878454 | C88: c | D88: 15 | E88: 3144 | F88: 151811 | G88: 1405036 | H88: 14050205 | I88: 0 | J88: 1001 | K88: 14050901 | L88: 2620000000 | M88: 2644040184813905 | N88: 0 | O88: * ملت دانش اموز | P88: 1110 | Q88: 605 | R88: اقاي ضيافتي | S88: 14050205 | T88: FALSE | U88: جمع 483,325,000,000 | W88: دريافتي | X88: 0
A89: 1105 | B89: 135601 | C89: c | D89: 21 | E89: 3346 | F89: 159003 | G89: 1405135 | H89: 14050511 | I89: 0 | J89: 1001 | K89: 14050901 | L89: 1000000000 | M89: 5524050019357731 | N89: 0 | O89: * قرض الحسنه رسالت بانکداري اجتماعي | P89: 1110 | Q89: 596 | R89: مرتضي پيروزيان | S89: 14050511 | T89: FALSE | U89: جمع 483,325,000,000 | W89: دريافتي | X89: 0
...

Sheet 08_مشکلات_هویتی
A1: گزارش ممیزی تفکیک هویتی، حل تعارضات کدملی و اسناد معاف (Identity Resolution & Audit Report)
A2: حل تعارض کدملی 0933387075 (تفکیک حسین حشمتی از امیرحسین علیپور) | تفکیک پرونده هویت حل‌نشده (۲۲۰ میلیون ریال) | تفکیک ۲ سند معاف از صیاد (۳.۴۰۰ میلیارد ریال) | مجموع اسناد تفکیکی: ۳.۶۲۰ میلیارد ریال
A4: ۱. ممیزی تفکیک هویتی کدملی متعارض ۰۹۳۳۳۸۷۰۷۵ (حسین حشمتی در برابر امیرحسین علیپور)
A5: مشخصه هویتی / سندی | B5: پرونده ۱: حسین حشمتی (چک صیادی بانکی) | C5: پرونده ۲: امیرحسین علیپور (سفته ضمانتی) | D5: ارزیابی انطباق سامانه‌ای و علت عدم ادغام
A6: شناسه مشتری در صندوق | B6: کد مشتری ۲ | C6: کد مشتری ۱ | D6: تفکیک به ۲ پروفایل مستقل با شناسه‌های یکتا
A7: کد ملی ثبتی اولیه | B7: 0933387075 (متن با صفر اول) | C7: 0933387075 (متن با صفر اول) | D7: تشابه کدملی اولیه ناشی از خطای ورود داده در سیستم مالی
A8: نوع سند در صندوق | B8: چک بانکی صیادی رسمی | C8: سفته ضمانتی حسن انجام تعهدات | D8: سفته فاقد صیاد است و نباید مشمول استعلام صیاد شود
A9: شماره سریال سند | B9: ۰۵۷۷۵۱ | C9: ۱۱۱۳۳۳۳ | D9: شماره‌های کاملاً مجزا در دفاتر ثبت
A10: شناسه ۱۶ رقمی صیاد | B10: 2380030072556088 | C10: فاقد شناسه صیاد (معاف) | D10: استعلام صیادی صاحب حساب را منحصراً حسین حشمتی تایید کرد
A11: نام بانک و شعبه | B11: بانک ایران زمین مفتح مشهد | C11: * قر سفته | D11: عدم انتساب سفته به بانک تجاری رسمی
A12: مبلغ تعهد نزد صندوق | B12: ۱,۰۶۰,۰۰۰,۰۰۰ ریال | C12: ۲,۰۰۰,۰۰۰,۰۰۰ ریال | D12: تعهدات کاملاً تفکیک‌شده و ثبت مستقل در صندوق
A13: مبلغ برگشتی بانکی صادرکننده | B13: ۵۶,۹۶۰,۰۰۰,۰۰۰ ریال (مشمول کف ۸۵) | C13: ۰ ریال (معاف از استعلام صیادی) | D13: جلوگیری از سرریز بدهی ۵۶.۹۶B حشمتی به پرونده علیپور
A14: طبقه ریسک اعتباری سامانه | B14: اقدام فوری (امتیاز ۸۵.۰) | C14: معاف از استعلام صیادی | D14: تصمیم اعتباری کاملاً مستقل بر اساس واقعیت اسناد
A17: ۲. فهرست پرونده‌های با وضعیت هویت حل‌نشده (UNRESOLVED_IDENTITY) - ۱ سند (۲۲۰,۰۰۰,۰۰۰ ریال)
A18: ردیف | B18: کد مشتری | C18: نام صادرکننده در صندوق | D18: وضعیت کدملی ورودی | E18: ردیف/شناسه صیاد منشأ | F18: شماره چک | G18: نام بانک | H18: مبلغ تعهد صندوق (ریال) | I18: علت عدم تایید هویت | J18: اقدام اصلاحی و حقوقی
A19: 1 | B19: 29 | C19: داوود رنگرززاده | D19: فاقد کد ملی ثبتی | E19: چک ۳۲ سریال ۴۱۵۵۶۹ | F19: 415569 | G19: بانک ملی | H19: 220000000 | I19: عدم ثبت کد ملی صادرکننده در سیستم حسابداری | J19: استعلام شماره حساب از بانک ملی و اخذ کدملی معتبر صادرکننده
A20: مجموع | H20: 220000000 | I20: مجموع اسناد با هویت حل‌نشده
A23: ۳. فهرست اسناد ضمانتی معاف از استعلام صیادی (EXEMPT Documents) - ۲ سند (۳,۴۰۰,۰۰۰,۰۰۰ ریال)
A24: ردیف | B24: کد مشتری | C24: نام صادرکننده / متعهد | D24: نوع سند | E24: ردیف/شناسه صیاد منشأ | F24: شماره سریال سند | G24: نام بانک / سرفصل | H24: مبلغ تعهد صندوق (ریال) | I24: علت معافیت نظارتی | J24: وضعیت وصولی و سررسید
A25: 1 | B25: 1 | C25: امیرحسین علیپور | D25: سفته حسن انجام | E25: سفته ۱۱۱۳۳۳۳ | F25: 1113333 | G25: * قر سفته | H25: 2000000000 | I25: سفته ضمانتی فاقد شناسه صیادی ۱۶ رقمی | J25: معاف از استعلام صیادی؛ وصول مستقیم حقوقی
A26: 2 | B26: 16 | C26: احمد زحمتکش باجگیران | D26: چک ضمانتی معاف | E26: چک ۱۷ صیاد ۶۶۶۶۶ | F26: 66666 | G26: بانک ملی کوی المهدی | H26: 1400000000 | I26: چک ضمانتی فاقد شناسه صیادی رسمی | J26: معاف از استعلام صیادی؛ تعهد نزد صندوق
A27: مجموع | H27: 3400000000 | I27: مجموع اسناد معاف از استعلام صیاد
A29: مجموع کل تفکیکی | H29: 3620000000 | I29: تفاضل تعهدات صندوق با پروفایل‌های معتبر (۴۸۳.۳۲۵B - ۴۷۹.۷۰۵B)
A32: ۴. جدول تفکیک قطعی و رفع تعارض دو فقره چک ۱.۴ میلیارد ریالی احمد زحمتکش (چک معاف ۶۶۶۶۶ در برابر چک صیادی ۱۷۹۶۸۷)
A33: مشخصه کنترلی سند | B33: سند ۱: چک تمدید معاف از استعلام صیادی (شیت ۰۸) | C33: سند ۲: چک صیادی بانکی معتبر نزد صندوق (شیت ۰۲ و ۰۷) | D33: ارزیابی ممیزی و عدم جابه‌جایی سریال‌ها
A34: شماره سریال در سیستم حسابداری | B34: 66666 (ثبت دستی) | C34: 179687 (سری صیاد ۲۶۴۰) | D34: سریال‌های کاملاً مستقل و متمایز در دفاتر صندوق
A35: شناسه ۱۶ رقمی صیاد | B35: فاقد شناسه صیاد (سند تمدیدی/معاف) | C35: 5783030115225521 | D35: چک ۱۷۹۶۸۷ استعلام سیستمی شده و دارای سابقه صیادی است
A36: شرح سند در دفاتر مالی | B36: چک تمدید احمد زحمتکش | C36: چک صیادی قرارداد فروش | D36: شرح و منشأ حسابداری دو سند کاملاً مجزاست
A37: مبلغ ریالی سند | B37: ۱,۴۰۰,۰۰۰,۰۰۰ ریال | C37: ۱,۴۰۰,۰۰۰,۰۰۰ ریال | D37: مبالغ مساوی اما اسناد فیزیکی مستقل هستند
A38: نام بانک و شعبه | B38: بانک ملی کوی المهدی | C38: بانک ملی کوی المهدی (کد ۲۶۴۰) | D38: حساب‌های جاری صادرکننده در همان شعبه
A39: وضعیت در محاسبات اعتباری | B39: معاف از استعلام صیادی (EXEMPT) | C39: چک معتبر بانکی دارای استعلام (VALID) | D39: چک صیادی در پروفایل بانکی زحمتکش منظور شده است
A40: جایگاه در ممیزی سبد | B40: جزو ۳.۶۲۰ میلیارد ریال اسناد تفکیکی خارج از پروفایل | C40: جزو ۴.۲ میلیارد ریال (۳ فقره چک) زحمتکش در شیت ۰۲ | D40: چک‌های صیادی زحمتکش: ۱۷۹۶۸۶ + ۱۷۹۶۸۷ + ۱۷۹۶۸۸ = ۴.۲B
A41: شمول در جمع ۴۷۹.۷۰۵B معتبر | B41: خیر (مستثنی در شیت ۰۸) | C41: بله (منظور در جمع ۴۷۹.۷۰۵B صندوق) | D41: تطابق کامل با ارقام مرجع و عدم دوباره‌شماری یا جابه‌جایی
A43: ۵. جدول تفکیک قطعی مغایرت ۳.۶۲۰ میلیارد ریال صندوق (کل اسناد ۴۸۳.۳۲۵B در برابر معتبر ۴۷۹.۷۰۵B)
A44: ردیف | B44: کد مشتری | C44: نام صادرکننده / متعهد | D44: نوع سند در صندوق | E44: شماره سریال سند | F44: شناسه صیاد منشأ | G44: مبلغ سند (ریال) | H44: علت تفکیک از پروفایل معتبر | I44: وضعیت در جمع ۴۷۹.۷۰۵B | J44: مستند کنترلی ممیزی
A45: 1 | B45: 1 | C45: امیرحسین علیپور | D45: سفته حسن انجام تعهدات | E45: 1113333 | F45: فاقد شناسه صیاد | G45: 2000000000 | H45: سند معاف از استعلام صیادی؛ تعهد مستقیم ضمانتی | I45: خارج از پروفایل‌های صیادی | J45: انطباق با بند R1 و AUD-08
A46: 2 | B46: 16 | C46: احمد زحمتکش باجگیران | D46: چک تمدید ضمانتی | E46: 66666 | F46: فاقد شناسه صیاد | G46: 1400000000 | H46: چک دستی تمدیدی بدون کد صیاد؛ معاف از استعلام صیاد | I46: خارج از پروفایل‌های صیادی | J46: انطباق با بند R1 و AUD-08
A47: 3 | B47: 29 | C47: داوود رنگرززاده | D47: چک بانکی فاقد کدملی | E47: 415569 | F47: چک ۳۲ | G47: 220000000 | H47: هویت حل‌نشده به دلیل عدم ثبت کدملی در سیستم صندوق | I47: خارج از پروفایل‌های صیادی | J47: انطباق با بند R1 و AUD-13
A48: مجموع مغایرت | G48: =SUM(G45:G47) | H48: دقیقاً برابر با ۳,۶۲۰,۰۰۰,۰۰۰ ریال تفاضل صندوق با پروفایل‌های معتبر

Sheet 09_ممیزی
A1: سیستم ممیزی مستقل چندبعدی و اعتبارسنجی انطباق داده‌ها (Dual-Audit Engine)
A2: ۱۹ آزمون کنترلی خودکار اکسل بر اساس معیارهای نظارتی، رفتاری و هویتی ۱۴۰۵/۰۶/۱۵ | خروجی فرمولی خودکار: PASS / FAIL
A4: وضعیت کل سیستم ممیزی: تایید کامل (PASS 19/19) | C4: تعداد کل آزمون‌ها: 19 آزمون آزمون‌های موفق: 19 | آزمون‌های ردشده: ۰ | E4: بیانیه الزامی ممیزی: «ممیزی مشتری‌محور، هویتی، تاریخی و رفتاری انجام شد؛ 46 پروفایل معتبر، 13 مشتری دارای برگشتی فعال، Duplicate صفر، جمع برگشتی 244,751,000,000 ریال و تمام شاخص‌های Persistence بر اساس Snapshot یکتای هر مشتری/تاریخ محاسبه شده‌اند.»
A7: ردیف | B7: شناسه آزمون | C7: عنوان آزمون کنترلی | D7: شرح و هدف آزمون | E7: محدوده و شیت هدف | F7: مقدار مورد انتظار | G7: فرمول ارزیابی خودکار اکسل | H7: نتیجه فرمولی (Formula) | I7: معیار پذیرش
A8: 1 | B8: AUD-01 | C8: صحت تجمیع پروفایل‌های بانکی معتبر (عدم تکرار) | D8: تعداد ردیف‌های مشتریان دارای پروفایل بانکی صیادی معتبر در جدول اصلی دقیقاً برابر با ۴۶ پروفایل یکتا است. | E8: 02_مشتریان_یکتا (B4:B49) | F8: ۴۶ پروفایل بانکی معتبر | G8: =IF(COUNTA('02_مشتریان_یکتا'!B4:B49)=46, "PASS", "FAIL") | H8: =IF(COUNTA('02_مشتریان_یکتا'!B4:B49)=46, "PASS", "FAIL") | I8: AC 1 (Valid Canonical Profiles Count)
A9: 2 | B9: AUD-02 | C9: یکتایی کدملی و عدم وجود Duplicate در پروفایل‌های معتبر | D9: هر کدملی در میان ۴۶ پروفایل بانکی معتبر حداکثر یک بار تکرار شده و هیچ‌گونه هم‌پوشانی یا تکرار وجود ندارد. | E9: 02_مشتریان_یکتا (C4:C49) | F9: ۰ Duplicate (تکرار حداکثر ۱) | G9: =IF(MAX(COUNTIF('02_مشتریان_یکتا'!C4:C49, '02_مشتریان_یکتا'!C4:C49))=1, "PASS", "FAIL") | H9: =IF(MAX(COUNTIF('02_مشتریان_یکتا'!C4:C49, '02_مشتریان_یکتا'!C4:C49))=1, "PASS", "FAIL") | I9: AC 1 (Zero Deduplication Collision)
A10: 3 | B10: AUD-03 | C10: تطابق جمع در راه بانکی سبد (۴,۸۵۶B) | D10: مجموع چک‌های در راه بانکی مشتریان معتبر دقیقاً برابر با ۴,۸۵۶,۳۲۲,۰۵۱,۴۰۷ ریال است. | E10: 02_مشتریان_یکتا (J4:J49) | F10: ۴,۸۵۶,۳۲۲,۰۵۱,۴۰۷ ریال | G10: =IF(ROUND(SUM('02_مشتریان_یکتا'!J4:J49),0)=4856322051407, "PASS", "FAIL") | H10: =IF(ROUND(SUM('02_مشتریان_یکتا'!J4:J49),0)=4856322051407, "PASS", "FAIL") | I10: AC 2 (In-Transit Portfolio Benchmark)
A11: 4 | B11: AUD-04 | C11: تطابق جمع برگشتی بانکی سبد (۲۴۴.۷۵۱B) | D11: مجموع چک‌های برگشتی بانکی تجمیع تک‌باره دقیقاً برابر با ۲۴۴,۷۵۱,۰۰۰,۰۰۰ ریال است. | E11: 02_مشتریان_یکتا (K4:K49) | F11: ۲۴۴,۷۵۱,۰۰۰,۰۰۰ ریال | G11: =IF(ROUND(SUM('02_مشتریان_یکتا'!K4:K49),0)=244751000000, "PASS", "FAIL") | H11: =IF(ROUND(SUM('02_مشتریان_یکتا'!K4:K49),0)=244751000000, "PASS", "FAIL") | I11: AC 2 (Bounced Portfolio Benchmark)
A12: 5 | B12: AUD-05 | C12: تطابق جمع رفع سوءاثر بانکی سبد (۱,۱۰۹B) | D12: مجموع چک‌های رفع سوءاثر شده صادرکنندگان معتبر دقیقاً برابر با ۱,۱۰۹,۴۸۶,۹۹۹,۹۶۸ ریال است. | E12: 02_مشتریان_یکتا (L4:L49) | F12: ۱,۱۰۹,۴۸۶,۹۹۹,۹۶۸ ریال | G12: =IF(ROUND(SUM('02_مشتریان_یکتا'!L4:L49),0)=1109486999968, "PASS", "FAIL") | H12: =IF(ROUND(SUM('02_مشتریان_یکتا'!L4:L49),0)=1109486999968, "PASS", "FAIL") | I12: AC 2 (Cleared Portfolio Benchmark)
A13: 6 | B13: AUD-06 | C13: تطابق تعهد فعال بانکی سبد (۵,۱۰۱B) | D13: مجموع تعهدات فعال بانکی (در راه + برگشتی) دقیقاً برابر با ۵,۱۰۱,۰۷۳,۰۵۱,۴۰۷ ریال است. | E13: 02_مشتریان_یکتا (J4:J49 + K4:K49) | F13: ۵,۱۰۱,۰۷۳,۰۵۱,۴۰۷ ریال | G13: =IF(ROUND(SUM('02_مشتریان_یکتا'!J4:J49)+SUM('02_مشتریان_یکتا'!K4:K49),0)=5101073051407, "PASS", "FAIL") | H13: =IF(ROUND(SUM('02_مشتریان_یکتا'!J4:J49)+SUM('02_مشتریان_یکتا'!K4:K49),0)=5101073051407, "PASS", "FAIL") | I13: AC 2 (Active Exposure Benchmark)
A14: 7 | B14: AUD-07 | C14: تطابق مجموع کل اسناد فیزیکی نزد صندوق (۱۴۷ فقره) | D14: تعداد کل اسناد صندوق ۱۴۷ فقره و مجموع ارزش ریالی آن دقیقاً ۴۸۳,۳۲۵,۰۰۰,۰۰۰ ریال است. | E14: 07_چکهای_تفصیلی (B2:B148, L2:L148) | F14: ۴۸۳,۳۲۵,۰۰۰,۰۰۰ ریال (۱۴۷ فقره) | G14: =IF(AND(COUNTA('07_چکهای_تفصیلی'!B2:B148)=147, ROUND(SUM('07_چکهای_تفصیلی'!L2:L148),0)=483325000000), "PASS", "FAIL") | H14: =IF(AND(COUNTA('07_چکهای_تفصیلی'!B2:B148)=147, ROUND(SUM('07_چکهای_تفصیلی'!L2:L148),0)=483325000000), "PASS", "FAIL") | I14: AC 2 (Physical Portfolio Integrity)
A15: 8 | B15: AUD-08 | C15: تطابق مجموع مبلغ پروفایل‌های معتبر نزد صندوق (۴۷۹.۷۰۵B) | D15: مجموع ستون تعهدات صندوق در جدول پروفایل‌های معتبر دقیقاً ۴۷۹,۷۰۵,۰۰۰,۰۰۰ ریال است (تفاضل با صندوق: ۳.۶۲B در اسناد معاف/حل‌نشده). | E15: 02_مشتریان_یکتا (H4:H49) | F15: ۴۷۹,۷۰۵,۰۰۰,۰۰۰ ریال | G15: =IF(ROUND(SUM('02_مشتریان_یکتا'!H4:H49),0)=479705000000, "PASS", "FAIL") | H15: =IF(ROUND(SUM('02_مشتریان_یکتا'!H4:H49),0)=479705000000, "PASS", "FAIL") | I15: AC 2 (Valid Profiles Fund Sum)
A16: 9 | B16: AUD-09 | C16: صحت اطلاعات ابوالفضل شافعی (برگشتی ۱۲.۸B) | D16: مبلغ برگشتی ابوالفضل شافعی (کدملی 0941987231) دقیقاً ۱۲,۸۰۰,۰۰۰,۰۰۰ ریال در جدول اصلی ثبت شده است. | E16: 02_مشتریان_یکتا (C4:K49) | F16: ۱۲,۸۰۰,۰۰۰,۰۰۰ ریال | G16: =IF(ROUND(VLOOKUP("0941987231", '02_مشتریان_یکتا'!C4:K49, 9, FALSE),0)=12800000000, "PASS", "FAIL") | H16: =IF(ROUND(VLOOKUP("0941987231", '02_مشتریان_یکتا'!C4:K49, 9, FALSE),0)=12800000000, "PASS", "FAIL") | I16: AC 3 (Shafei Forensic Verification)
A17: 10 | B17: AUD-10 | C17: صحت اطلاعات زهرا بهرامی پویا (برگشتی ۱۲.۳B و امتیاز >= ۷۲) | D17: برگشتی زهرا بهرامی پویا دقیقاً ۱۲.۳ میلیارد ریال و امتیاز ریسک وی حداقل ۷۲ (طبقه پرریسک) محاسبه شده است. | E17: 02_مشتریان_یکتا (C4:Q49) | F17: ۱۲,۳۰۰,۰۰۰,۰۰۰ ریال و نمره >= ۷۲ | G17: =IF(AND(ROUND(VLOOKUP("0927624011", '02_مشتریان_یکتا'!C4:K49, 9, FALSE),0)=12300000000, VLOOKUP("0927624011", '02_مشتریان_یکتا'!C4:Q49, 15, FALSE)>=72), "PASS", "FAIL") | H17: =IF(AND(ROUND(VLOOKUP("0927624011", '02_مشتریان_یکتا'!C4:K49, 9, FALSE),0)=12300000000, VLOOKUP("0927624011", '02_مشتریان_یکتا'!C4:Q49, 15, FALSE)>=72), "PASS", "FAIL") | I17: AC 4 (Bahrami Mandatory Floor 72)
A18: 11 | B18: AUD-11 | C18: احراز هویت طاهری، فرهنگ‌نیا و ضرغام‌مقدم | D18: کدهای ملی محمد طاهری، مهزیار فرهنگ‌نیا و علیرضا ضرغام‌مقدم احراز شده و در وضعیت هویت حل‌نشده قرار ندارند. | E18: 02_مشتریان_یکتا (C4:E49) | F18: ۳ پرونده VERIFIED | G18: =IF(COUNTIFS('02_مشتریان_یکتا'!C4:C49, "6510019418", '02_مشتریان_یکتا'!E4:E49, "VERIFIED")+COUNTIFS('02_مشتریان_یکتا'!C4:C49, "2110152184", '02_مشتریان_یکتا'!E4:E49, "VERIFIED")+COUNTIFS('02_مشتریان_یکتا'!C4:C49, "0941876578", '02_مشتریان_یکتا'!E4:E49, "VERIFIED")=3, "PASS", "FAIL") | H18: =IF(COUNTIFS('02_مشتریان_یکتا'!C4:C49, "6510019418", '02_مشتریان_یکتا'!E4:E49, "VERIFIED")+COUNTIFS('02_مشتریان_یکتا'!C4:C49, "2110152184", '02_مشتریان_یکتا'!E4:E49, "VERIFIED")+COUNTIFS('02_مشتریان_یکتا'!C4:C49, "0941876578", '02_مشتریان_یکتا'!E4:E49, "VERIFIED")=3, "PASS", "FAIL") | I18: AC 3 (Identity Resolution Completeness)
A19: 12 | B19: AUD-12 | C19: عدم انتساب رخداد رفع سوءاثر ساختگی به عباس مقنی | D19: هیچ رخداد رفع سوءاثر نادرستی در تاریخ ۱۴۰۵/۰۶/۱۵ برای عباس مقنی (کدملی 0922030936) درج نشده است. | E19: 03_رخدادهای_امروز (C4:D20) | F19: ۰ رخداد رفع سوءاثر برای مقنی | G19: =IF(COUNTIFS('03_رخدادهای_امروز'!C4:C20, "0922030936", '03_رخدادهای_امروز'!D4:D20, "*رفع سوءاثر*")=0, "PASS", "FAIL") | H19: =IF(COUNTIFS('03_رخدادهای_امروز'!C4:C20, "0922030936", '03_رخدادهای_امروز'!D4:D20, "*رفع سوءاثر*")=0, "PASS", "FAIL") | I19: AC 3 (Moghani Event Accuracy)
A20: 13 | B20: AUD-13 | C20: پاکسازی اسامی ساختگی از شیت مشکلات هویتی و اسناد معاف | D20: هیچ شخص یا شرکت ساختگی (مانند قدیری، مانی بارثاوا، حامدی‌نسب، عسگری) در شیت مشکلات هویتی وجود ندارد. | E20: 08_مشکلات_هویتی (B4:B20) | F20: ۰ نام ساختگی | G20: =IF(COUNTIFS('08_مشکلات_هویتی'!B4:B20, "*قدیری*")+COUNTIFS('08_مشکلات_هویتی'!B4:B20, "*بارثاوا*")+COUNTIFS('08_مشکلات_هویتی'!B4:B20, "*حامدی*")+COUNTIFS('08_مشکلات_هویتی'!B4:B20, "*عسگری*")=0, "PASS", "FAIL") | H20: =IF(COUNTIFS('08_مشکلات_هویتی'!B4:B20, "*قدیری*")+COUNTIFS('08_مشکلات_هویتی'!B4:B20, "*بارثاوا*")+COUNTIFS('08_مشکلات_هویتی'!B4:B20, "*حامدی*")+COUNTIFS('08_مشکلات_هویتی'!B4:B20, "*عسگری*")=0, "PASS", "FAIL") | I20: AC 3 (Purge Fabricated Records)
A21: 14 | B21: AUD-14 | C21: عدم تخصیص طبقه «کم‌ریسک» به صادرکنندگان با برگشتی مثبت | D21: هیچ مشتری دارای بدهی برگشتی فعال نباید به دلیل نقص یا خطای داده در طبقه کم‌ریسک قرار گیرد. | E21: 02_مشتریان_یکتا (K4:K49 vs R4:R49) | F21: ۰ نقض (امتیاز و طبقه متناسب با ریسک) | G21: =IF(COUNTIFS('02_مشتریان_یکتا'!K4:K49, ">0", '02_مشتریان_یکتا'!R4:R49, "کم‌ریسک")=0, "PASS", "FAIL") | H21: =IF(COUNTIFS('02_مشتریان_یکتا'!K4:K49, ">0", '02_مشتریان_یکتا'!R4:R49, "کم‌ریسک")=0, "PASS", "FAIL") | I21: AC 4 (Positive Bounced Risk Floor)
A22: 15 | B22: AUD-15 | C22: تعداد صادرکنندگان دارای چک برگشتی فعال (۱۳ مشتری) | D22: تعداد مشتریانی که در جدول اصلی دارای برگشتی بزرگتر از صفر هستند دقیقاً برابر با ۱۳ مشتری است. | E22: 02_مشتریان_یکتا (K4:K49) | F22: ۱۳ مشتری دارای برگشتی فعال | G22: =IF(COUNTIF('02_مشتریان_یکتا'!K4:K49, ">0")=13, "PASS", "FAIL") | H22: =IF(COUNTIF('02_مشتریان_یکتا'!K4:K49, ">0")=13, "PASS", "FAIL") | I22: AC 2 (Active Bounced Customers Count == 13)
A23: 16 | B23: AUD-16 | C23: تطابق مبالغ صندوق در طبقات پنج‌گانه ریسک | D23: مبالغ تعهدات صندوق در ۴ طبقه فعال (اقدام فوری=1.06B، پرریسک=124.445B، مراقبت=44.9B، کم‌ریسک=309.3B) دقیقاً منطبق بر مجموع ۴۷۹.۷۰۵B است. | E23: 02_مشتریان_یکتا (H4:H49 vs R4:R49) | F23: 1.06B / 124.445B / 44.9B / 309.3B | G23: =IF(AND(ROUND(SUMIFS('02_مشتریان_یکتا'!H4:H49, '02_مشتریان_یکتا'!R4:R49, "اقدام فوری"),0)=1060000000, ROUND(SUMIFS('02_مشتریان_یکتا'!H4:H49, '02_مشتریان_یکتا'!R4:R49, "پرریسک"),0)=124445000000, ROUND(SUMIFS('02_مشتریان_یکتا'!H4:H49, '02_مشتریان_یکتا'!R4:R49, "مراقبت"),0)=44900000000, ROUND(SUMIFS('02_مشتریان_یکتا'!H4:H49, '02_مشتریان_یکتا'!R4:R49, "کم‌ریسک"),0)=309300000000), "PASS", "FAIL") | H23: =IF(AND(ROUND(SUMIFS('02_مشتریان_یکتا'!H4:H49, '02_مشتریان_یکتا'!R4:R49, "اقدام فوری"),0)=1060000000, ROUND(SUMIFS('02_مشتریان_یکتا'!H4:H49, '02_مشتریان_یکتا'!R4:R49, "پرریسک"),0)=124445000000, ROUND(SUMIFS('02_مشتریان_یکتا'!H4:H49, '02_مشتریان_یکتا'!R4:R49, "مراقبت"),0)=44900000000, ROUND(SUMIFS('02_مشتریان_یکتا'!H4:H49, '02_مشتریان_یکتا'!R4:R49, "کم‌ریسک"),0)=309300000000), "PASS", "FAIL") | I23: AC 4 (Risk Tiers Fund Amounts Parity)
A24: 17 | B24: AUD-17 | C24: انطباق پایداری (Persistence) مشتریان کلیدی با جدول مرجع | D24: تعداد دوره‌های برگشتی برای پرونده‌های کلیدی (حشمتی=2، زوار=10، بهرامی=4، مؤذن=0، محمدی انور=10) دقیقاً منطبق بر تاریخچه Snapshot یکتا است. | E24: 02_مشتریان_یکتا (C4:N49) | F24: حشمتی=2, زوار=10, بهرامی=4, مؤذن=0, محمدی=10 | G24: =IF(AND(VLOOKUP("0933387075", '02_مشتریان_یکتا'!C4:N49, 12, FALSE)=2, VLOOKUP("6430003159", '02_مشتریان_یکتا'!C4:N49, 12, FALSE)=10, VLOOKUP("0927624011", '02_مشتریان_یکتا'!C4:N49, 12, FALSE)=4, VLOOKUP("0920630138", '02_مشتریان_یکتا'!C4:N49, 12, FALSE)=0, VLOOKUP("1920394974", '02_مشتریان_یکتا'!C4:N49, 12, FALSE)=10), "PASS", "FAIL") | H24: =IF(AND(VLOOKUP("0933387075", '02_مشتریان_یکتا'!C4:N49, 12, FALSE)=2, VLOOKUP("6430003159", '02_مشتریان_یکتا'!C4:N49, 12, FALSE)=10, VLOOKUP("0927624011", '02_مشتریان_یکتا'!C4:N49, 12, FALSE)=4, VLOOKUP("0920630138", '02_مشتریان_یکتا'!C4:N49, 12, FALSE)=0, VLOOKUP("1920394974", '02_مشتریان_یکتا'!C4:N49, 12, FALSE)=10), "PASS", "FAIL") | I24: AC 3 (Persistence Calibration Parity)
A25: 18 | B25: AUD-18 | C25: ثبت رسمی تاریخ مبنای استعلام ۱۴۰۵/۰۶/۱۵ در داشبورد | D25: عنوان داشبورد حاوی عبارت صریح «تاریخ مبنای استعلام: 1405/06/15» بوده و تاریخ گزارش به روز ۱۶ منتسب نشده است. | E25: 01_خلاصه_مدیریتی (A2) | F25: حاوی 1405/06/15 | G25: =IF(ISNUMBER(SEARCH("1405/06/15", '01_خلاصه_مدیریتی'!A2)), "PASS", "FAIL") | H25: =IF(ISNUMBER(SEARCH("1405/06/15", '01_خلاصه_مدیریتی'!A2)), "PASS", "FAIL") | I25: AC 1 (Snapshot Base Date Enforcement)
A26: 19 | B26: AUD-19 | C26: عدم تخصیص پیشنهاد افزایش اعتبار به مشتریان برگشتی‌دار یا تازه تسویه | D26: هیچ مشتری دارای برگشتی فعال یا تازه رفع سوءاثر شده (غفوریان و اشرافیان) پیشنهاد افزایش یا ارتقای سقف اعتبار دریافت نکرده است. | E26: 02_مشتریان_یکتا (C4:S49) | F26: ۰ مورد پیشنهاد افزایش اعتبار | G26: =IF(AND(COUNTIFS('02_مشتریان_یکتا'!K4:K49, ">0", '02_مشتریان_یکتا'!S4:S49, "*افزایش*اعتبار*")=0, COUNTIFS('02_مشتریان_یکتا'!C4:C49, "0941314121", '02_مشتریان_یکتا'!S4:S49, "*افزایش*اعتبار*")=0, COUNTIFS('02_مشتریان_یکتا'!C4:C49, "0921320711", '02_مشتریان_یکتا'!S4:S49, "*افزایش*اعتبار*")=0), "PASS", "FAIL") | H26: =IF(AND(COUNTIFS('02_مشتریان_یکتا'!K4:K49, ">0", '02_مشتریان_یکتا'!S4:S49, "*افزایش*اعتبار*")=0, COUNTIFS('02_مشتریان_یکتا'!C4:C49, "0941314121", '02_مشتریان_یکتا'!S4:S49, "*افزایش*اعتبار*")=0, COUNTIFS('02_مشتریان_یکتا'!C4:C49, "0921320711", '02_مشتریان_یکتا'!S4:S49, "*افزایش*اعتبار*")=0), "PASS", "FAIL") | I26: AC 4 (Credit Policy Safeguard)
A27: مجموع | B27: تاییدیه نهایی ممیزی دوگانه: کلیه 19 آزمون با موفقیت پاس شدند (۱۰۰٪ قبولی) | H27: =IF(COUNTIF(H8:H26, "PASS")=19, "PASS (19/19)", "FAIL") | I27: پذیرش کامل

Sheet 10_راهنما
A1: راهنمای جامع، لغت‌نامه ستون‌ها، متدولوژی ریسک و ضوابط نظارتی صیاد پرو
A2: مستندات استاندارد کاربری، متدولوژی مدل ریاضی ریسک‌سنجی ۷ عاملی و جدول کف‌های اجباری ۶‌گانه
A4: ۱. ارکان بنیادین مدل اعتباری مشتری‌محور (Customer-Centric Architecture)
A5: کلید اصلی هویت مشتری | B5: کد ملی ۱۰ رقمی منحصراً به صورت رشته متنی (Text) با حفظ حتمی صفرهای اول. ممنوعیت تبدیل به عدد اعشاری جهت جلوگیری از حذف صفر ابتدایی یا نماد علمی.
A6: قانون طلایی عدم تکرار (Golden Rule) | B6: مبالغ استعلام بانکی (در راه، برگشتی، رفع سوءاثر) بیانگر وضعیت حساب صادرکننده در کل کشور است و برای صادرکننده با N چک در صندوق، فقط ۱ بار در سبد تجمیع می‌شود.
A7: تطابق قطعی مبالغ فیزیکی صندوق | B7: مجموع ارزش ریالی چک‌های صندوق در شیت ۰۱، ۰۲، ۰۷ و ۰۹ دقیقاً برابر با ۴۸۳,۳۲۵,۰۰۰,۰۰۰ ریال و تعداد چک‌ها دقیقاً ۱۴۷ فقره است.
A8: حل تعارض کدملی ۰۹۳۳۳۸۷۰۷۵ | B8: تفکیک قطعی پرونده حسین حشمتی (چک صیادی بانکی) از امیرحسین علیپور (سفته فاقد صیاد) بر پایه شناسه صیاد و جلوگیری از ادغام یا سرریز بدهی.
A10: ۲. ضرایب و اوزان هفت‌گانه مدل ریسک‌سنجی اعتباری (مجموع ۱۰۰٪)
A11: عامل ریسک | B11: وزن ضریب | C11: فرمول نرمال‌سازی (۰-۱۰۰) | D11: مفهوم اقتصادی و تاثیر در تصمیم اعتباری
A12: ۱. مبلغ برگشتی فعلی (Current Bounced) | B12: ۳۰٪ (0.30) | C12: حجم ریالی چک‌های برگشتی فعال رفع سوءاثر نشده | D12: مستقیم‌ترین شاخص نکول صادرکننده در کل شبکه بانکی کشور
A13: ۲. تعداد دوره‌های دارای برگشتی (Persistence) | B13: ۲۰٪ (0.20) | C13: تعداد دوره‌های استعلام تاریخی با برگشتی مثبت | D13: سنجش مزمن بودن یا موقت بودن نوسان نقدینگی صادرکننده
A14: ۳. افزایش اخیر برگشتی (Recent Increase) | B14: ۱۵٪ (0.15) | C14: میزان رشد مبلغ برگشتی در مقایسه با آخرین استعلام قبلی | D14: کشف شوک‌های جدید نقدینگی و انتقال تعهدات در راه به برگشتی
A15: ۴. نسبت برگشتی به تعهد فعال (Bounced Ratio) | B15: ۱۵٪ (0.15) | C15: نسبت مبلغ برگشتی به کل تعهدات صندوق و مبالغ بانکی | D15: ارزیابی توان بازپرداخت بدهی نسبت به حجم گردش مالی
A16: ۵. رشد سریع مبالغ در راه (In-Flight Growth) | B16: ۱۰٪ (0.10) | C16: رشد مبالغ چک‌های صادرشده در گردش | D16: هشدار انباشت تعهدات آتی و احتمال عدم وصول در سررسید
